#VRML_SIM R2020b utf8
WorldInfo {
  coordinateSystem "NUE"
}
Viewpoint {
  orientation 0.6623466159724404 0.31995901062625487 -0.6774386996835395 6.1757982423757305
  position 0.009503829110356986 0.3756516202873009 4.262771709949053
  follow "robot"
}
TexturedBackground {
}
TexturedBackgroundLight {
}
Robot {
  translation -1.80309e-12 0.41 -5.43899e-09
  rotation -6.180701830239702e-09 0.9999999999999999 6.1827213635154806e-09 -1.5704599999999682
  children [
    DEF IMU InertialUnit {
      translation 0 0.01 0
      name "IMU"
      boundingObject Shape {
        appearance GalvanizedMetal {
        }
      }
    }
    DEF BODY Shape {
      appearance PBRAppearance {
        baseColor 0.917647 0.145098 0.145098
        roughness 1
        metalness 0
      }
      geometry Box {
        size 0.1 0.05 0.2
      }
    }
    DEF WHEEL1 HingeJoint {
      jointParameters HingeJointParameters {
        position 349.5280055712788
        anchor 0.06 0 0.05
      }
      device [
        RotationalMotor {
          name "wheel1"
          maxVelocity 50
        }
      ]
      endPoint Solid {
        translation 0.06 0 0.05
        rotation -1 0 0 2.3303716307780316
        children [
          DEF WHEEL Transform {
            rotation 0 0 1 1.5708
            children [
              Shape {
                appearance PBRAppearance {
                  baseColor 0.305882 0.898039 0.25098
                  roughness 1
                  metalness 0
                }
                geometry Cylinder {
                  height 0.02
                  radius 0.04
                  subdivision 24
                }
              }
            ]
          }
        ]
        boundingObject USE WHEEL
        physics Physics {
        }
      }
    }
    DEF WHEEL2 HingeJoint {
      jointParameters HingeJointParameters {
        position 194.50321575987954
        anchor -0.06 0 0.05
      }
      device [
        RotationalMotor {
          name "wheel2"
          maxVelocity 50
        }
      ]
      endPoint Solid {
        translation -0.06 0 0.05
        rotation 1 0 0 6.007656544491944
        children [
          USE WHEEL
        ]
        name "solid(1)"
        boundingObject USE WHEEL
        physics Physics {
        }
      }
    }
    DEF WHEEL3 HingeJoint {
      jointParameters HingeJointParameters {
        position 349.5280144662652
        anchor 0.06 0 -0.05
      }
      device [
        RotationalMotor {
          name "wheel3"
          maxVelocity 50
        }
      ]
      endPoint Solid {
        translation 0.06 0 -0.05
        rotation -1 0 0 2.3303627357916663
        children [
          USE WHEEL
        ]
        name "solid(2)"
        boundingObject USE WHEEL
        physics Physics {
        }
      }
    }
    DEF WHEEL4 HingeJoint {
      jointParameters HingeJointParameters {
        position 194.5032237803993
        anchor -0.06 0 -0.05
      }
      device [
        RotationalMotor {
          name "wheel4"
          maxVelocity 50
        }
      ]
      endPoint Solid {
        translation -0.06 0 -0.05
        rotation 1 0 0 6.007664565011715
        children [
          USE WHEEL
        ]
        name "solid(3)"
        boundingObject USE WHEEL
        physics Physics {
        }
      }
    }
  ]
  boundingObject USE BODY
  physics Physics {
    density -1
    mass 1
  }
  controller "cntrIP"
}
DEF CYLINDER Solid {
  translation 0 0.17 1.73333e-07
  rotation 1 0 0 -1.5707953071795862
  children [
    Shape {
      appearance CarpetFibers {
      }
      geometry DEF CYL_GEOM Cylinder {
        height 0.5
        radius 0.2
      }
    }
  ]
  boundingObject USE CYL_GEOM
  physics Physics {
    density -1
    mass 2
    centerOfMass [
      0 0 0
    ]
    inertiaMatrix [
      15.2891 20.1062 15.2891
      0 0 0
    ]
  }
}
DEF FLOOR Solid {
  translation 0 -0.06 0
  children [
    Shape {
      appearance BlanketFabric {
      }
      geometry DEF FLOOR_GEOM Box {
        size 10 0.05 4
      }
    }
  ]
  name "solid(1)"
  boundingObject USE FLOOR_GEOM
}
