#VRML_SIM R2020b utf8
WorldInfo {
  coordinateSystem "NUE"
}
Viewpoint {
  orientation 0.7633178826690612 -0.1656550869846852 -0.6244230954679026 6.163206054648087
  position -0.1935420710867478 0.6629064546516855 2.1518498854203596
  follow "robot"
}
TexturedBackground {
}
TexturedBackgroundLight {
}
Robot {
  translation 0 0.64 0
  rotation -6.180701830239702e-09 0.9999999999999999 6.1827213635154806e-09 -1.5704599999999682
  scale 2 2 2
  children [
    Receiver {
      channel 1
    }
    DEF IMU InertialUnit {
      translation 0 0.01 0
      name "IMU"
      boundingObject Shape {
        appearance GalvanizedMetal {
        }
      }
    }
    DEF BODY Shape {
      appearance PBRAppearance {
        baseColor 0.917647 0.145098 0.145098
        roughness 1
        metalness 0
      }
      geometry Box {
        size 0.1 0.05 0.2
      }
    }
    DEF WHEEL1 HingeJoint {
      jointParameters HingeJointParameters {
        position 349.5280055712788
        anchor 0.06 0 0.05
      }
      device [
        RotationalMotor {
          name "wheel1"
          maxVelocity 50
        }
      ]
      endPoint Solid {
        translation 0.06 0 0.05
        rotation -1 0 0 2.3303716307780316
        children [
          DEF WHEEL Transform {
            rotation 0 0 1 1.5708
            children [
              Shape {
                appearance PBRAppearance {
                  baseColor 0.305882 0.898039 0.25098
                  roughness 1
                  metalness 0
                }
                geometry Cylinder {
                  height 0.02
                  radius 0.04
                  subdivision 50
                }
              }
            ]
          }
        ]
        boundingObject USE WHEEL
        physics Physics {
        }
      }
    }
    DEF WHEEL2 HingeJoint {
      jointParameters HingeJointParameters {
        position 194.50321575987954
        anchor -0.06 0 0.05
      }
      device [
        RotationalMotor {
          name "wheel2"
          maxVelocity 50
        }
      ]
      endPoint Solid {
        translation -0.06 0 0.05
        rotation 1 0 0 6.007656544491944
        children [
          USE WHEEL
        ]
        name "solid(1)"
        boundingObject USE WHEEL
        physics Physics {
        }
      }
    }
    DEF WHEEL3 HingeJoint {
      jointParameters HingeJointParameters {
        position 349.5280144662652
        anchor 0.06 0 -0.05
      }
      device [
        RotationalMotor {
          name "wheel3"
          maxVelocity 50
        }
      ]
      endPoint Solid {
        translation 0.06 0 -0.05
        rotation -1 0 0 2.3303627357916663
        children [
          USE WHEEL
        ]
        name "solid(2)"
        boundingObject USE WHEEL
        physics Physics {
        }
      }
    }
    DEF WHEEL4 HingeJoint {
      jointParameters HingeJointParameters {
        position 194.5032237803993
        anchor -0.06 0 -0.05
      }
      device [
        RotationalMotor {
          name "wheel4"
          maxVelocity 50
        }
      ]
      endPoint Solid {
        translation -0.06 0 -0.05
        rotation 1 0 0 6.007664565011715
        children [
          USE WHEEL
        ]
        name "solid(3)"
        boundingObject USE WHEEL
        physics Physics {
        }
      }
    }
  ]
  boundingObject USE BODY
  physics Physics {
    density -1
    mass 1
  }
  controller "cntrIP"
}
DEF FLOOR Solid {
  translation 0 -0.06 0
  children [
    Shape {
      appearance BlanketFabric {
      }
      geometry DEF FLOOR_GEOM Box {
        size 400 0.05 4
      }
    }
  ]
  name "solid(1)"
  boundingObject USE FLOOR_GEOM
}
DEF valec Robot {
  translation 0 0.27 0
  rotation 1 0 0 -1.5707953071795862
  children [
    Emitter {
      channel 1
    }
    Gyro {
    }
    Shape {
      appearance CorrugatedMetal {
      }
      geometry DEF CYL_GEOM Cylinder {
        height 0.5
        radius 0.3
        subdivision 100
      }
    }
  ]
  name "valec"
  boundingObject USE CYL_GEOM
  physics Physics {
    density -1
    mass 4
    centerOfMass [
      0 0 0
    ]
    inertiaMatrix [
      1.937315469713706 1.2566370614359177 1.937315469713706
      0 0 0
    ]
  }
  controller "valec_controler"
}
