#VRML_SIM R2020b utf8
WorldInfo {
  coordinateSystem "NUE"
}
Viewpoint {
  orientation 0.02274772402402569 0.9996640519706252 0.012422731156961832 3.181532774656471
  position -1.8702192429984745 0.19681741830847285 -1.8228001952754627
  follow "robot"
}
TexturedBackground {
}
TexturedBackgroundLight {
}
Floor {
}
Robot {
  translation -1.8135076587067755 0.03964930926021508 0.49854411241112645
  rotation 0.001496310372973604 0.9999977151384211 0.0015266870030204956 -1.5704634122744026
  children [
    DEF BODY Shape {
      appearance PBRAppearance {
        baseColor 0.917647 0.145098 0.145098
        roughness 1
        metalness 0
      }
      geometry Box {
        size 0.1 0.05 0.2
      }
    }
    Transform {
      translation -0.02 0.03 0
      children [
        HingeJoint {
          jointParameters HingeJointParameters {
            anchor 0.5 0 0
          }
          device [
            PositionSensor {
              name "angle_sensor"
            }
          ]
          endPoint DEF STICK Solid {
            translation 0.019999989764104498 0.15999983821848535 1.0830634999958733e-11
            rotation 4.0762126445773354e-05 0.02672546283621861 0.9996428101950412 5.960464477539063e-08
            children [
              Transform {
                children [
                  DEF STICK Shape {
                    appearance PBRAppearance {
                      baseColor 0 1 1
                      metalness 0
                    }
                    geometry DEF STICK_SHAPE Cylinder {
                      height 0.3
                      radius 0.005
                    }
                  }
                ]
              }
            ]
            name "stick"
            boundingObject USE STICK_SHAPE
            physics DEF STICK_STICK Physics {
              mass 1
              centerOfMass [
                0 0.5 0
              ]
              damping DEF STICK Damping {
              }
            }
          }
        }
        DEF HINGE_BODY Shape {
          appearance PBRAppearance {
            baseColor 0 0 1
            metalness 0
          }
          geometry Box {
            size 0.02 0.06 0.05
          }
        }
      ]
    }
    DEF WHEEL1 HingeJoint {
      jointParameters HingeJointParameters {
        position 349.5280055532794
        anchor 0.06 0 0.05
      }
      device [
        RotationalMotor {
          name "wheel1"
          maxVelocity 50
        }
      ]
      endPoint Solid {
        translation 0.06 0 0.05
        rotation -1 0 0 2.3303716487774433
        children [
          DEF WHEEL Transform {
            rotation 0 0 1 1.5708
            children [
              Shape {
                appearance PBRAppearance {
                  baseColor 0.305882 0.898039 0.25098
                  roughness 1
                  metalness 0
                }
                geometry Cylinder {
                  height 0.02
                  radius 0.04
                  subdivision 24
                }
              }
            ]
          }
        ]
        boundingObject USE WHEEL
        physics Physics {
        }
      }
    }
    DEF WHEEL2 HingeJoint {
      jointParameters HingeJointParameters {
        position 194.5032157415205
        anchor -0.06 0 0.05
      }
      device [
        RotationalMotor {
          name "wheel2"
          maxVelocity 50
        }
      ]
      endPoint Solid {
        translation -0.06 0 0.05
        rotation 1 0 0 6.007656526132911
        children [
          USE WHEEL
        ]
        name "solid(1)"
        boundingObject USE WHEEL
        physics Physics {
        }
      }
    }
    DEF WHEEL3 HingeJoint {
      jointParameters HingeJointParameters {
        position 349.52801448462463
        anchor 0.06 0 -0.05
      }
      device [
        RotationalMotor {
          name "wheel3"
          maxVelocity 50
        }
      ]
      endPoint Solid {
        translation 0.06 0 -0.05
        rotation -1 0 0 2.3303627174322084
        children [
          USE WHEEL
        ]
        name "solid(2)"
        boundingObject USE WHEEL
        physics Physics {
        }
      }
    }
    DEF WHEEL4 HingeJoint {
      jointParameters HingeJointParameters {
        position 194.503223798399
        anchor -0.06 0 -0.05
      }
      device [
        RotationalMotor {
          name "wheel4"
          maxVelocity 50
        }
      ]
      endPoint Solid {
        translation -0.06 0 -0.05
        rotation 1 0 0 6.007664583011412
        children [
          USE WHEEL
        ]
        name "solid(3)"
        boundingObject USE WHEEL
        physics Physics {
        }
      }
    }
    DEF DS_RIGHT DistanceSensor {
      translation -0.03 0 0.1
      rotation 0 1 0 -1.87079
      children [
        Shape {
          appearance PBRAppearance {
            baseColor 0.184314 0.596078 0.847059
            roughness 1
            metalness 0
          }
          geometry Box {
            size 0.01 0.01 0.01
          }
        }
      ]
      name "ds_right"
    }
    DEF DS_LEFT DistanceSensor {
      translation 0.03 0 0.1
      rotation 0 1 0 -1.27079
      children [
        Shape {
          appearance PBRAppearance {
            baseColor 0.184314 0.596078 0.847059
            roughness 1
            metalness 0
          }
          geometry Box {
            size 0.01 0.01 0.01
          }
        }
      ]
      name "ds_left"
    }
  ]
  boundingObject USE BODY
  physics Physics {
    density -1
    mass 1
  }
  controller "cntrIP"
}
