#VRML_SIM R2020b utf8
WorldInfo {
  coordinateSystem "NUE"
}
Viewpoint {
  orientation 0.08051541170103892 -0.9882497325605022 -0.12992203266847469 4.1708844818577235
  position 0.6075697518519872 0.31783585531644354 -0.10524682035371868
}
TexturedBackground {
}
TexturedBackgroundLight {
}
Floor {
}
Robot {
  translation -0.08000000000012679 0.03972097932317502 0.15266999999998931
  rotation -1.4506817308092897e-06 0.9476387030991839 -0.3193444666600506 -1.4066473770467288e-07
  children [
    DEF BODY Shape {
      appearance PBRAppearance {
        baseColor 0.917647 0.145098 0.145098
        roughness 1
        metalness 0
      }
      geometry Box {
        size 0.1 0.05 0.2
      }
    }
    Transform {
      translation 0 0.05 0
      children [
        DEF HINGE_BODY Shape {
          appearance PBRAppearance {
          }
          geometry Box {
            size 0.05 0.05 0.1
          }
        }
      ]
    }
    DEF WHEEL1 HingeJoint {
      jointParameters HingeJointParameters {
        position 4.191998709968097
        anchor 0.06 0 0.05
      }
      device [
        RotationalMotor {
          name "wheel1"
        }
      ]
      endPoint Solid {
        translation 0.06 0 0.05
        rotation 0.9999999999999999 0 0 4.191998709968097
        children [
          DEF WHEEL Transform {
            rotation 0 0 1 1.5708
            children [
              Shape {
                appearance PBRAppearance {
                  baseColor 0.305882 0.898039 0.25098
                  roughness 1
                  metalness 0
                }
                geometry Cylinder {
                  height 0.02
                  radius 0.04
                  subdivision 24
                }
              }
            ]
          }
        ]
        boundingObject USE WHEEL
        physics Physics {
        }
        linearVelocity 9.136930743934016e-14 2.4109314809371952e-08 -1.1912277588689508e-12
        angularVelocity -3.196543381116016e-11 5.991878128232623e-12 3.3048183345858066e-14
      }
    }
    DEF WHEEL2 HingeJoint {
      jointParameters HingeJointParameters {
        position 4.191998709064712
        anchor -0.06 0 0.05
      }
      device [
        RotationalMotor {
          name "wheel2"
        }
      ]
      endPoint Solid {
        translation -0.06 0 0.05
        rotation 1 0 0 4.191998709064712
        children [
          USE WHEEL
        ]
        name "solid(1)"
        boundingObject USE WHEEL
        physics Physics {
        }
        linearVelocity 9.146626433968702e-14 2.4109967600553164e-08 -9.677974488125022e-13
        angularVelocity -3.194772759619993e-11 5.991878163382871e-12 2.7951186337758933e-14
      }
    }
    DEF WHEEL3 HingeJoint {
      jointParameters HingeJointParameters {
        position 4.1920011161335875
        anchor 0.06 0 -0.05
      }
      device [
        RotationalMotor {
          name "wheel3"
        }
      ]
      endPoint Solid {
        translation 0.06 0 -0.05
        rotation 0.9999999999999999 0 0 4.1920011161335875
        children [
          USE WHEEL
        ]
        name "solid(2)"
        boundingObject USE WHEEL
        physics Physics {
        }
        linearVelocity -9.473897848690414e-14 2.410932343220919e-08 -1.1912763785366316e-12
        angularVelocity -3.196521273382747e-11 5.991878222619611e-12 4.8339312074394654e-14
      }
    }
    DEF WHEEL4 HingeJoint {
      jointParameters HingeJointParameters {
        position 4.192001115150601
        anchor -0.06 0 -0.05
      }
      device [
        RotationalMotor {
          name "wheel4"
        }
      ]
      endPoint Solid {
        translation -0.06 0 -0.05
        rotation 1 0 0 4.192001115150601
        children [
          USE WHEEL
        ]
        name "solid(3)"
        boundingObject USE WHEEL
        physics Physics {
        }
        linearVelocity -9.45952977818815e-14 2.4109976859498203e-08 8.010527136649505e-13
        angularVelocity 3.2142329403375813e-11 5.991881167046012e-12 4.595643655391252e-14
      }
    }
    DEF DS_RIGHT DistanceSensor {
      translation -0.03 0 0.1
      rotation 0 1 0 -1.87079
      children [
        Shape {
          appearance PBRAppearance {
            baseColor 0.184314 0.596078 0.847059
            roughness 1
            metalness 0
          }
          geometry Box {
            size 0.01 0.01 0.01
          }
        }
      ]
      name "ds_right"
    }
    DEF DS_LEFT DistanceSensor {
      translation 0.03 0 0.1
      rotation 0 1 0 -1.27079
      children [
        Shape {
          appearance PBRAppearance {
            baseColor 0.184314 0.596078 0.847059
            roughness 1
            metalness 0
          }
          geometry Box {
            size 0.01 0.01 0.01
          }
        }
      ]
      name "ds_left"
    }
  ]
  boundingObject USE BODY
  physics Physics {
    density -1
    mass 1
  }
  controller "cntrIP"
  linearVelocity -1.6950168604101864e-15 -1.7870650026452496e-10 -6.373274790594178e-13
  angularVelocity 1.0068813138531641e-13 5.9932122019584266e-12 1.534769087673805e-14
}
