#VRML_SIM R2020b utf8
WorldInfo {
  coordinateSystem "NUE"
  contactProperties [
    ContactProperties {
      softCFM 1e-05
    }
  ]
}
Viewpoint {
  orientation 0.5532098533833588 -0.46430583746243625 -0.6916494396859353 5.982965412639086
  position 0.381774434801912 1.1948338068852333 2.6318512801996286
  follow "robot"
}
TexturedBackground {
}
TexturedBackgroundLight {
}
Robot {
  translation 0 0.592931 0
  rotation 0 1 0 -1.5641466299726126
  children [
    DEF WEIGHT Solid {
      translation 0 0.5 0
      children [
        Shape {
          appearance Grass {
          }
          geometry DEF WEIGHT_GEOM Cylinder {
            height 1
            radius 0.17
          }
        }
      ]
      name "solid(4)"
      boundingObject USE WEIGHT_GEOM
      physics Physics {
        density -1
        mass 30
        centerOfMass [
          0 0 0
        ]
        inertiaMatrix [
          0.5361651462126582 0.5361651462126582 0.5361651462126582
          0 0 0
        ]
      }
    }
    Receiver {
      channel 1
    }
    DEF IMU InertialUnit {
      translation 0 0.01 0
      name "IMU"
      boundingObject Shape {
        appearance GalvanizedMetal {
        }
      }
    }
    DEF BODY Shape {
      appearance PBRAppearance {
        baseColor 0.917647 0.145098 0.145098
        roughness 1
        metalness 0
      }
      geometry Box {
        size 0.4 0.01 0.7
      }
    }
    DEF WHEEL1 HingeJoint {
      jointParameters HingeJointParameters {
        anchor 0.06 -0.07 0.25
      }
      device [
        RotationalMotor {
          name "wheel1"
          maxVelocity 50
        }
      ]
      endPoint Solid {
        translation 0.15 -0.07 0.25
        rotation 1 0 0 0
        children [
          DEF WHEEL Transform {
            rotation 0 0 1 1.5708
            children [
              Shape {
                appearance PBRAppearance {
                  baseColor 0.305882 0.898039 0.25098
                  roughness 1
                  metalness 0
                }
                geometry Cylinder {
                  height 0.02
                  radius 0.06
                  subdivision 50
                }
              }
            ]
          }
        ]
        boundingObject USE WHEEL
        physics Physics {
        }
      }
    }
    DEF WHEEL2 HingeJoint {
      jointParameters HingeJointParameters {
        position 1761.0553335611894
        anchor -0.06 -0.07 0.25
      }
      device [
        RotationalMotor {
          name "wheel2"
          maxVelocity 50
        }
      ]
      endPoint Solid {
        translation -0.15 -0.07 0.25
        rotation 0.9999999999458121 9.27174479256132e-06 -4.733966376302296e-06 2.1314524330565616
        children [
          USE WHEEL
        ]
        name "solid(1)"
        boundingObject USE WHEEL
        physics Physics {
        }
      }
    }
    DEF WHEEL3 HingeJoint {
      jointParameters HingeJointParameters {
        position 1916.0802408051923
        anchor 0.06 -0.07 -0.25
      }
      device [
        RotationalMotor {
          name "wheel3"
          maxVelocity 50
        }
      ]
      endPoint Solid {
        translation 0.15 -0.07 -0.25
        rotation 0.9999999717792875 0.00020185068481668036 0.00012529056501845774 0.07672583813348349
        children [
          USE WHEEL
        ]
        name "solid(2)"
        boundingObject USE WHEEL
        physics Physics {
        }
      }
    }
    DEF WHEEL4 HingeJoint {
      jointParameters HingeJointParameters {
        position 1761.0554515389808
        anchor -0.06 -0.07 -0.25
      }
      device [
        RotationalMotor {
          name "wheel4"
          maxVelocity 50
        }
      ]
      endPoint Solid {
        translation -0.15 -0.07 -0.25
        rotation 0.999999999945802 9.273550636857881e-06 -4.73257991801614e-06 2.131569046943568
        children [
          USE WHEEL
        ]
        name "solid(3)"
        boundingObject USE WHEEL
        physics Physics {
        }
      }
    }
  ]
  boundingObject USE BODY
  physics Physics {
    density -1
    mass 1
  }
  controller "cntrIP"
}
DEF FLOOR Solid {
  translation 0 -0.06 0
  children [
    Shape {
      appearance BlanketFabric {
      }
      geometry DEF FLOOR_GEOM Box {
        size 400 0.05 4
      }
    }
  ]
  name "solid(1)"
  boundingObject USE FLOOR_GEOM
}
DEF valec Robot {
  translation 0 0.258551 0
  rotation 1 0 0 -1.5707953071795862
  children [
    Emitter {
      channel 1
    }
    Gyro {
    }
    Shape {
      appearance CorrugatedMetal {
      }
      geometry DEF CYL_GEOM Cylinder {
        height 0.5
        radius 0.3
        subdivision 100
      }
    }
  ]
  name "valec"
  boundingObject USE CYL_GEOM
  physics Physics {
    density -1
    mass 4
    centerOfMass [
      0 0 0
    ]
    inertiaMatrix [
      1.937315469713706 1.2566370614359177 1.937315469713706
      0 0 0
    ]
  }
  controller "valec_controler"
}
