#VRML_SIM R2020b utf8
WorldInfo {
  coordinateSystem "NUE"
  contactProperties [
    ContactProperties {
      softCFM 1e-05
    }
  ]
}
Viewpoint {
  orientation -0.7842891275161911 0.6202354978150029 0.014088708601821098 0.285108317997136
  position 2.3309167198524823 1.5577352125914232 4.765968944041597
  follow "robot"
}
TexturedBackground {
}
TexturedBackgroundLight {
}
Robot {
  translation -4.690752038051477e-27 0.40288556000000003 3.1192491952979307e-29
  rotation 5.9679764857794e-27 1 5.9284226910757145e-27 -1.5641466299726126
  children [
    DEF WEIGHT Solid {
      translation 0 0.5 0
      children [
        Shape {
          appearance Grass {
          }
          geometry DEF WEIGHT_GEOM Cylinder {
            height 1
            radius 0.17
          }
        }
      ]
      name "solid(4)"
      boundingObject USE WEIGHT_GEOM
      physics Physics {
        density -1
        mass 15
        centerOfMass [
          0 0 0
        ]
        inertiaMatrix [
          0.5361651462126582 0.5361651462126582 0.5361651462126582
          0 0 0
        ]
      }
    }
    Receiver {
      channel 1
    }
    DEF IMU InertialUnit {
      translation 0 0.01 0
      name "IMU"
      boundingObject Shape {
        appearance GalvanizedMetal {
        }
      }
    }
    DEF BODY Shape {
      appearance PBRAppearance {
        baseColor 0.917647 0.145098 0.145098
        roughness 1
        metalness 0
      }
      geometry Box {
        size 0.4 0.01 0.7
      }
    }
    DEF WHEEL1 HingeJoint {
      jointParameters HingeJointParameters {
        position -1.479895337719638e-30
        anchor 0.15 -0.07 0.25
        suspensionSpringConstant 10000
        suspensionDampingConstant 1000
        suspensionAxis 0 1 0
      }
      device [
        RotationalMotor {
          name "wheel1"
          maxVelocity 50
        }
      ]
      endPoint Solid {
        translation 0.14999999999999997 -0.07000000000000006 0.24999999999999997
        rotation 1 0 0 0
        children [
          DEF WHEEL Transform {
            rotation 0 0 1 1.5708
            children [
              Shape {
                appearance PBRAppearance {
                  baseColor 0.305882 0.898039 0.25098
                  roughness 1
                  metalness 0
                }
                geometry Cylinder {
                  height 0.02
                  radius 0.1
                  subdivision 50
                }
              }
            ]
          }
        ]
        boundingObject USE WHEEL
        physics Physics {
        }
      }
    }
    DEF WHEEL2 HingeJoint {
      jointParameters HingeJointParameters {
        position 1761.0553335611894
        anchor -0.15 -0.07 0.25
        suspensionSpringConstant 10000
        suspensionDampingConstant 1000
        suspensionAxis 0 1 0
      }
      device [
        RotationalMotor {
          name "wheel2"
          maxVelocity 50
        }
      ]
      endPoint Solid {
        translation -0.14999999999999997 -0.07000000000000006 0.24999999999999997
        rotation 1 0 0 0
        children [
          USE WHEEL
        ]
        name "solid(1)"
        boundingObject USE WHEEL
        physics Physics {
        }
      }
    }
    DEF WHEEL3 HingeJoint {
      jointParameters HingeJointParameters {
        position 1916.0802408051923
        anchor 0.15 -0.07 -0.25
        suspensionSpringConstant 10000
        suspensionDampingConstant 1000
        suspensionAxis 0 1 0
      }
      device [
        RotationalMotor {
          name "wheel3"
          maxVelocity 50
        }
      ]
      endPoint Solid {
        translation 0.15 -0.07000000000000006 -0.24999999999999997
        rotation 1 0 0 0
        children [
          USE WHEEL
        ]
        name "solid(2)"
        boundingObject USE WHEEL
        physics Physics {
        }
      }
    }
    DEF WHEEL4 HingeJoint {
      jointParameters HingeJointParameters {
        position 1761.0554515389808
        anchor -0.15 -0.07 -0.25
        suspensionSpringConstant 10000
        suspensionDampingConstant 1000
        suspensionAxis 0 1 0
      }
      device [
        RotationalMotor {
          name "wheel4"
          maxVelocity 50
        }
      ]
      endPoint Solid {
        translation -0.14999999999999994 -0.07000000000000008 -0.24999999999999997
        rotation 1 0 0 0
        children [
          USE WHEEL
        ]
        name "solid(3)"
        boundingObject USE WHEEL
        physics Physics {
        }
      }
    }
  ]
  boundingObject USE BODY
  physics Physics {
    density -1
    mass 1
  }
  controller "cntrIP"
}
DEF FLOOR Solid {
  translation 0 -0.06 0
  children [
    Shape {
      appearance BlanketFabric {
      }
      geometry DEF FLOOR_GEOM Box {
        size 400 0.05 4
      }
    }
  ]
  name "solid(1)"
  boundingObject USE FLOOR_GEOM
}
DEF valec Robot {
  translation 0 0.15850556000000002 0
  rotation 0.9999999999999999 0 0 -1.5707953071795862
  children [
    Emitter {
      channel 1
    }
    Gyro {
    }
    Shape {
      appearance CorrugatedMetal {
      }
      geometry DEF CYL_GEOM Cylinder {
        height 0.5
        radius 0.2
        subdivision 100
      }
    }
  ]
  name "valec"
  boundingObject USE CYL_GEOM
  physics Physics {
    density -1
    mass 1
    centerOfMass [
      0 0 0
    ]
    inertiaMatrix [
      1.937315469713706 1.2566370614359177 1.937315469713706
      0 0 0
    ]
  }
  controller "valec_controler"
}
