#VRML_SIM R2020b utf8
WorldInfo {
  info [
    "Thanks to Mehdi Ghanavati, Shahid Chamran University"
  ]
  title "Omni-wheels"
  basicTimeStep 8
  coordinateSystem "NUE"
  contactProperties [
    ContactProperties {
      coulombFriction [
        1, 1
      ]
      frictionRotation 1 1
      softCFM 0.0001
    }
  ]
}
Viewpoint {
  orientation 1 0 0 4.71238898038469
  position -0.0001462874944322048 5.18432519301435 5.1775045539408946e-05
  follow "robot"
}
TexturedBackground {
}
TexturedBackgroundLight {
}
RectangleArena {
  floorSize 50 50
}
DEF OMNI_WHEELS Robot {
  translation 0 0.54 0
  children [
    InertialUnit {
      name "IMU"
    }
    DEF wheel1 Solid {
      translation 0 -0.134142 0.0314627
      rotation 1 0 0 0.785398
      children [
        DEF WHEEL1 HingeJoint {
          jointParameters HingeJointParameters {
            axis 0 0 1
            anchor 0 0 0.1
            suspensionSpringConstant 50000
            suspensionDampingConstant 10000
            suspensionAxis 0 1 0
          }
          device [
            RotationalMotor {
              name "wheel1"
              maxVelocity 50
            }
          ]
          endPoint Solid {
            translation 0 0 0.1
            rotation 0 0 1 0
            children [
              DEF Wheel_Half_A Transform {
                translation 0 0 0.02
                rotation 0 0 1 0.39
                children [
                  DEF WHEEL_TRANS Transform {
                    translation 0 0 0.02
                    rotation 1 0 0 1.5708
                    children [
                      DEF WHEEL_SHAPE Shape {
                        appearance PBRAppearance {
                          baseColor 0.678431 0.847059 0.901961
                          roughness 1
                          metalness 0
                        }
                        geometry Cylinder {
                          height 0.02
                          radius 0.05
                          subdivision 20
                        }
                      }
                    ]
                  }
                  DEF sr8 HingeJoint {
                    jointParameters HingeJointParameters {
                      axis -0.707107 0.707107 0
                      anchor 0.03535 0.03535 0.02
                    }
                    endPoint Solid {
                      translation 0.03535 0.03535 0.02
                      rotation -0.7071067811865476 0.7071067811865476 0 0
                      children [
                        DEF r8 Transform {
                          rotation 0 0 1 0.76
                          children [
                            DEF SMALL_WHEEL_SHAPE Shape {
                              appearance PBRAppearance {
                                baseColor 1 0.752941 0.796078
                                roughness 1
                                metalness 0
                              }
                              geometry Capsule {
                                height 0.015
                                radius 0.01
                              }
                            }
                          ]
                        }
                      ]
                      name "sr8(1)"
                      boundingObject USE r8
                      physics Physics {
                        density -1
                        mass 0.1
                      }
                    }
                  }
                  DEF sr7 HingeJoint {
                    jointParameters HingeJointParameters {
                      axis -0.707107 0.707107 0
                      anchor -0.03535 -0.03535 0.02
                    }
                    endPoint Solid {
                      translation -0.03535 -0.03535 0.02
                      rotation -0.7071067811865476 0.7071067811865476 0 0
                      children [
                        DEF r7 Transform {
                          rotation 0 0 1 0.76
                          children [
                            DEF SMALL_WHEEL_SHAPE Shape {
                              appearance PBRAppearance {
                                baseColor 1 0.752941 0.796078
                                roughness 1
                                metalness 0
                              }
                              geometry Capsule {
                                height 0.015
                                radius 0.01
                              }
                            }
                          ]
                        }
                      ]
                      name "sr7(1)"
                      boundingObject USE r7
                      physics Physics {
                        density -1
                        mass 0.1
                      }
                    }
                  }
                  DEF sr6 HingeJoint {
                    jointParameters HingeJointParameters {
                      axis 0 1 0
                      anchor 0.05 0 0.02
                    }
                    endPoint Solid {
                      translation 0.05 0 0.02
                      children [
                        DEF r6 Transform {
                          children [
                            DEF SMALL_WHEEL_SHAPE Shape {
                              appearance PBRAppearance {
                                baseColor 1 0.752941 0.796078
                                roughness 1
                                metalness 0
                              }
                              geometry Capsule {
                                height 0.015
                                radius 0.01
                              }
                            }
                          ]
                        }
                      ]
                      name "sr6(1)"
                      boundingObject USE r6
                      physics Physics {
                        density -1
                        mass 0.1
                      }
                    }
                  }
                  DEF sr5 HingeJoint {
                    jointParameters HingeJointParameters {
                      axis 0 1 0
                      anchor -0.05 0 0.02
                    }
                    endPoint Solid {
                      translation -0.05 0 0.02
                      children [
                        DEF r5 Transform {
                          children [
                            DEF SMALL_WHEEL_SHAPE Shape {
                              appearance PBRAppearance {
                                baseColor 1 0.752941 0.796078
                                roughness 1
                                metalness 0
                              }
                              geometry Capsule {
                                height 0.015
                                radius 0.01
                              }
                            }
                          ]
                        }
                      ]
                      name "sr5(1)"
                      boundingObject USE r5
                      physics Physics {
                        density -1
                        mass 0.1
                      }
                    }
                  }
                  DEF sr4 HingeJoint {
                    jointParameters HingeJointParameters {
                      axis 0.707107 0.707107 0
                      anchor 0.03535 -0.03535 0.02
                    }
                    endPoint Solid {
                      translation 0.03535 -0.03535 0.02
                      rotation 0.7071067811865476 0.7071067811865476 0 0
                      children [
                        DEF r4 Transform {
                          rotation 0 0 1 2.27
                          children [
                            DEF SMALL_WHEEL_SHAPE Shape {
                              appearance PBRAppearance {
                                baseColor 1 0.752941 0.796078
                                roughness 1
                                metalness 0
                              }
                              geometry Capsule {
                                height 0.015
                                radius 0.01
                              }
                            }
                          ]
                        }
                      ]
                      name "sr4(1)"
                      boundingObject USE r4
                      physics Physics {
                        density -1
                        mass 0.1
                      }
                    }
                  }
                  DEF sr3 HingeJoint {
                    jointParameters HingeJointParameters {
                      anchor 0 -0.05 0.02
                    }
                    endPoint Solid {
                      translation 0 -0.05 0.02
                      rotation 1 0 0 0
                      children [
                        DEF r3 Transform {
                          rotation 0 0 1 1.5708
                          children [
                            DEF SMALL_WHEEL_SHAPE Shape {
                              appearance PBRAppearance {
                                baseColor 1 0.752941 0.796078
                                roughness 1
                                metalness 0
                              }
                              geometry Capsule {
                                height 0.015
                                radius 0.01
                              }
                            }
                          ]
                        }
                      ]
                      name "sr3(1)"
                      boundingObject USE r3
                      physics Physics {
                        density -1
                        mass 0.1
                      }
                    }
                  }
                  DEF sr2 HingeJoint {
                    jointParameters HingeJointParameters {
                      axis 0.707107 0.707107 0
                      anchor -0.03535 0.03535 0.02
                    }
                    endPoint Solid {
                      translation -0.03535 0.03535 0.02
                      rotation 0.7071067811865476 0.7071067811865476 0 0
                      children [
                        DEF r2 Transform {
                          rotation 0 0 1 2.27
                          children [
                            DEF SMALL_WHEEL_SHAPE Shape {
                              appearance PBRAppearance {
                                baseColor 1 0.752941 0.796078
                                roughness 1
                                metalness 0
                              }
                              geometry Capsule {
                                height 0.015
                                radius 0.01
                              }
                            }
                          ]
                        }
                      ]
                      name "sr2(1)"
                      boundingObject USE r2
                      physics Physics {
                        density -1
                        mass 0.1
                      }
                    }
                  }
                  DEF sr1 HingeJoint {
                    jointParameters HingeJointParameters {
                      anchor 0 0.05 0.02
                    }
                    endPoint Solid {
                      translation 0 0.05 0.02
                      rotation 1 0 0 0
                      children [
                        DEF r1 Transform {
                          rotation 0 0 1 1.5708
                          children [
                            DEF SMALL_WHEEL_SHAPE Shape {
                              appearance PBRAppearance {
                                baseColor 1 0.752941 0.796078
                                roughness 1
                                metalness 0
                              }
                              geometry Capsule {
                                height 0.015
                                radius 0.01
                              }
                            }
                          ]
                        }
                      ]
                      name "sr1(1)"
                      boundingObject USE r1
                      physics Physics {
                        density -1
                        mass 0.1
                      }
                    }
                  }
                ]
              }
              DEF Wheel_Half_B Transform {
                children [
                  DEF WHEEL_TRANS Transform {
                    translation 0 0 0.02
                    rotation 1 0 0 1.5708
                    children [
                      DEF WHEEL_SHAPE Shape {
                        appearance PBRAppearance {
                          baseColor 0.678431 0.847059 0.901961
                          roughness 1
                          metalness 0
                        }
                        geometry Cylinder {
                          height 0.02
                          radius 0.05
                          subdivision 20
                        }
                      }
                    ]
                  }
                  DEF sr8 HingeJoint {
                    jointParameters HingeJointParameters {
                      axis -0.707107 0.707107 0
                      anchor 0.03535 0.03535 0.02
                    }
                    endPoint Solid {
                      translation 0.03535 0.03535 0.02
                      rotation -0.7071067811865476 0.7071067811865476 0 0
                      children [
                        DEF r8 Transform {
                          rotation 0 0 1 0.76
                          children [
                            DEF SMALL_WHEEL_SHAPE Shape {
                              appearance PBRAppearance {
                                baseColor 1 0.752941 0.796078
                                roughness 1
                                metalness 0
                              }
                              geometry Capsule {
                                height 0.015
                                radius 0.01
                              }
                            }
                          ]
                        }
                      ]
                      name "sr8"
                      boundingObject USE r8
                      physics Physics {
                        density -1
                        mass 0.1
                      }
                    }
                  }
                  DEF sr7 HingeJoint {
                    jointParameters HingeJointParameters {
                      axis -0.707107 0.707107 0
                      anchor -0.03535 -0.03535 0.02
                    }
                    endPoint Solid {
                      translation -0.03535 -0.03535 0.02
                      rotation -0.7071067811865476 0.7071067811865476 0 0
                      children [
                        DEF r7 Transform {
                          rotation 0 0 1 0.76
                          children [
                            DEF SMALL_WHEEL_SHAPE Shape {
                              appearance PBRAppearance {
                                baseColor 1 0.752941 0.796078
                                roughness 1
                                metalness 0
                              }
                              geometry Capsule {
                                height 0.015
                                radius 0.01
                              }
                            }
                          ]
                        }
                      ]
                      name "sr7"
                      boundingObject USE r7
                      physics Physics {
                        density -1
                        mass 0.1
                      }
                    }
                  }
                  DEF sr6 HingeJoint {
                    jointParameters HingeJointParameters {
                      axis 0 1 0
                      anchor 0.05 0 0.02
                    }
                    endPoint Solid {
                      translation 0.05 0 0.02
                      children [
                        DEF r6 Transform {
                          children [
                            DEF SMALL_WHEEL_SHAPE Shape {
                              appearance PBRAppearance {
                                baseColor 1 0.752941 0.796078
                                roughness 1
                                metalness 0
                              }
                              geometry Capsule {
                                height 0.015
                                radius 0.01
                              }
                            }
                          ]
                        }
                      ]
                      name "sr6"
                      boundingObject USE r6
                      physics Physics {
                        density -1
                        mass 0.1
                      }
                    }
                  }
                  DEF sr5 HingeJoint {
                    jointParameters HingeJointParameters {
                      axis 0 1 0
                      anchor -0.05 0 0.02
                    }
                    endPoint Solid {
                      translation -0.05 0 0.02
                      children [
                        DEF r5 Transform {
                          children [
                            DEF SMALL_WHEEL_SHAPE Shape {
                              appearance PBRAppearance {
                                baseColor 1 0.752941 0.796078
                                roughness 1
                                metalness 0
                              }
                              geometry Capsule {
                                height 0.015
                                radius 0.01
                              }
                            }
                          ]
                        }
                      ]
                      name "sr5"
                      boundingObject USE r5
                      physics Physics {
                        density -1
                        mass 0.1
                      }
                    }
                  }
                  DEF sr4 HingeJoint {
                    jointParameters HingeJointParameters {
                      axis 0.707107 0.707107 0
                      anchor 0.03535 -0.03535 0.02
                    }
                    endPoint Solid {
                      translation 0.03535 -0.03535 0.02
                      rotation 0.7071067811865476 0.7071067811865476 0 0
                      children [
                        DEF r4 Transform {
                          rotation 0 0 1 2.27
                          children [
                            DEF SMALL_WHEEL_SHAPE Shape {
                              appearance PBRAppearance {
                                baseColor 1 0.752941 0.796078
                                roughness 1
                                metalness 0
                              }
                              geometry Capsule {
                                height 0.015
                                radius 0.01
                              }
                            }
                          ]
                        }
                      ]
                      name "sr4"
                      boundingObject USE r4
                      physics Physics {
                        density -1
                        mass 0.1
                      }
                    }
                  }
                  DEF sr3 HingeJoint {
                    jointParameters HingeJointParameters {
                      anchor 0 -0.05 0.02
                    }
                    endPoint Solid {
                      translation 0 -0.05 0.02
                      rotation 1 0 0 0
                      children [
                        DEF r3 Transform {
                          rotation 0 0 1 1.5708
                          children [
                            DEF SMALL_WHEEL_SHAPE Shape {
                              appearance PBRAppearance {
                                baseColor 1 0.752941 0.796078
                                roughness 1
                                metalness 0
                              }
                              geometry Capsule {
                                height 0.015
                                radius 0.01
                              }
                            }
                          ]
                        }
                      ]
                      name "sr3"
                      boundingObject USE r3
                      physics Physics {
                        density -1
                        mass 0.1
                      }
                    }
                  }
                  DEF sr2 HingeJoint {
                    jointParameters HingeJointParameters {
                      axis 0.707107 0.707107 0
                      anchor -0.03535 0.03535 0.02
                    }
                    endPoint Solid {
                      translation -0.03535 0.03535 0.02
                      rotation 0.7071067811865476 0.7071067811865476 0 0
                      children [
                        DEF r2 Transform {
                          rotation 0 0 1 2.27
                          children [
                            DEF SMALL_WHEEL_SHAPE Shape {
                              appearance PBRAppearance {
                                baseColor 1 0.752941 0.796078
                                roughness 1
                                metalness 0
                              }
                              geometry Capsule {
                                height 0.015
                                radius 0.01
                              }
                            }
                          ]
                        }
                      ]
                      name "sr2"
                      boundingObject USE r2
                      physics Physics {
                        density -1
                        mass 0.1
                      }
                    }
                  }
                  DEF sr1 HingeJoint {
                    jointParameters HingeJointParameters {
                      anchor 0 0.05 0.02
                    }
                    endPoint Solid {
                      translation 0 0.05 0.02
                      rotation 1 0 0 0
                      children [
                        DEF r1 Transform {
                          rotation 0 0 1 1.5708
                          children [
                            DEF SMALL_WHEEL_SHAPE Shape {
                              appearance PBRAppearance {
                                baseColor 1 0.752941 0.796078
                                roughness 1
                                metalness 0
                              }
                              geometry Capsule {
                                height 0.015
                                radius 0.01
                              }
                            }
                          ]
                        }
                      ]
                      name "sr1"
                      boundingObject USE r1
                      physics Physics {
                        density -1
                        mass 0.1
                      }
                    }
                  }
                ]
              }
            ]
            boundingObject Transform {
              translation 0 0 0.02
              rotation 1 0 0 1.5708
              children [
                DEF wheel1 Shape {
                  appearance PBRAppearance {
                    baseColor 0.8 0.8 0.8
                    transparency 0.12999999523162842
                    roughness 1
                    metalness 0
                    emissiveColor 0 1 0
                  }
                  geometry Cylinder {
                    height 0.02
                    radius 0.05
                  }
                }
              ]
            }
            physics Physics {
            }
          }
        }
      ]
      name "wheel 1"
      boundingObject DEF dummy_object Transform {
        translation 0 -4.40784e-07 0.12
        rotation 1 0 0 1.5708
        children [
          USE wheel1
        ]
      }
      physics Physics {
      }
    }
    DEF wheel2 Solid {
      translation 0.0272473 -0.134142 -0.0157316
      rotation 0.2157380479632118 0.9021232005614055 -0.3736720830753473 2.18124
      children [
        DEF WHEEL1 HingeJoint {
          jointParameters HingeJointParameters {
            axis 0 0 1
            anchor 0 0 0.1
            suspensionSpringConstant 50000
            suspensionDampingConstant 10000
            suspensionAxis 0 1 0
          }
          device [
            RotationalMotor {
              name "wheel2"
              maxVelocity 50
            }
          ]
          endPoint Solid {
            translation 0 0 0.1
            rotation 0 0 1 0
            children [
              DEF Wheel_Half_A Transform {
                translation 0 0 0.02
                rotation 0 0 1 0.39
                children [
                  DEF WHEEL_TRANS Transform {
                    translation 0 0 0.02
                    rotation 1 0 0 1.5708
                    children [
                      DEF WHEEL_SHAPE Shape {
                        appearance PBRAppearance {
                          baseColor 0.678431 0.847059 0.901961
                          roughness 1
                          metalness 0
                        }
                        geometry Cylinder {
                          height 0.02
                          radius 0.05
                          subdivision 20
                        }
                      }
                    ]
                  }
                  DEF sr8 HingeJoint {
                    jointParameters HingeJointParameters {
                      axis -0.707107 0.707107 0
                      anchor 0.03535 0.03535 0.02
                    }
                    endPoint Solid {
                      translation 0.03535 0.03535 0.02
                      rotation -0.7071067811865476 0.7071067811865476 0 0
                      children [
                        DEF r8 Transform {
                          rotation 0 0 1 0.76
                          children [
                            DEF SMALL_WHEEL_SHAPE Shape {
                              appearance PBRAppearance {
                                baseColor 1 0.752941 0.796078
                                roughness 1
                                metalness 0
                              }
                              geometry Capsule {
                                height 0.015
                                radius 0.01
                              }
                            }
                          ]
                        }
                      ]
                      name "sr8(1)"
                      boundingObject USE r8
                      physics Physics {
                        density -1
                        mass 0.1
                      }
                    }
                  }
                  DEF sr7 HingeJoint {
                    jointParameters HingeJointParameters {
                      axis -0.707107 0.707107 0
                      anchor -0.03535 -0.03535 0.02
                    }
                    endPoint Solid {
                      translation -0.03535 -0.03535 0.02
                      rotation -0.7071067811865476 0.7071067811865476 0 0
                      children [
                        DEF r7 Transform {
                          rotation 0 0 1 0.76
                          children [
                            DEF SMALL_WHEEL_SHAPE Shape {
                              appearance PBRAppearance {
                                baseColor 1 0.752941 0.796078
                                roughness 1
                                metalness 0
                              }
                              geometry Capsule {
                                height 0.015
                                radius 0.01
                              }
                            }
                          ]
                        }
                      ]
                      name "sr7(1)"
                      boundingObject USE r7
                      physics Physics {
                        density -1
                        mass 0.1
                      }
                    }
                  }
                  DEF sr6 HingeJoint {
                    jointParameters HingeJointParameters {
                      axis 0 1 0
                      anchor 0.05 0 0.02
                    }
                    endPoint Solid {
                      translation 0.05 0 0.02
                      children [
                        DEF r6 Transform {
                          children [
                            DEF SMALL_WHEEL_SHAPE Shape {
                              appearance PBRAppearance {
                                baseColor 1 0.752941 0.796078
                                roughness 1
                                metalness 0
                              }
                              geometry Capsule {
                                height 0.015
                                radius 0.01
                              }
                            }
                          ]
                        }
                      ]
                      name "sr6(1)"
                      boundingObject USE r6
                      physics Physics {
                        density -1
                        mass 0.1
                      }
                    }
                  }
                  DEF sr5 HingeJoint {
                    jointParameters HingeJointParameters {
                      axis 0 1 0
                      anchor -0.05 0 0.02
                    }
                    endPoint Solid {
                      translation -0.05 0 0.02
                      children [
                        DEF r5 Transform {
                          children [
                            DEF SMALL_WHEEL_SHAPE Shape {
                              appearance PBRAppearance {
                                baseColor 1 0.752941 0.796078
                                roughness 1
                                metalness 0
                              }
                              geometry Capsule {
                                height 0.015
                                radius 0.01
                              }
                            }
                          ]
                        }
                      ]
                      name "sr5(1)"
                      boundingObject USE r5
                      physics Physics {
                        density -1
                        mass 0.1
                      }
                    }
                  }
                  DEF sr4 HingeJoint {
                    jointParameters HingeJointParameters {
                      axis 0.707107 0.707107 0
                      anchor 0.03535 -0.03535 0.02
                    }
                    endPoint Solid {
                      translation 0.03535 -0.03535 0.02
                      rotation 0.7071067811865476 0.7071067811865476 0 0
                      children [
                        DEF r4 Transform {
                          rotation 0 0 1 2.27
                          children [
                            DEF SMALL_WHEEL_SHAPE Shape {
                              appearance PBRAppearance {
                                baseColor 1 0.752941 0.796078
                                roughness 1
                                metalness 0
                              }
                              geometry Capsule {
                                height 0.015
                                radius 0.01
                              }
                            }
                          ]
                        }
                      ]
                      name "sr4(1)"
                      boundingObject USE r4
                      physics Physics {
                        density -1
                        mass 0.1
                      }
                    }
                  }
                  DEF sr3 HingeJoint {
                    jointParameters HingeJointParameters {
                      anchor 0 -0.05 0.02
                    }
                    endPoint Solid {
                      translation 0 -0.05 0.02
                      rotation 1 0 0 0
                      children [
                        DEF r3 Transform {
                          rotation 0 0 1 1.5708
                          children [
                            DEF SMALL_WHEEL_SHAPE Shape {
                              appearance PBRAppearance {
                                baseColor 1 0.752941 0.796078
                                roughness 1
                                metalness 0
                              }
                              geometry Capsule {
                                height 0.015
                                radius 0.01
                              }
                            }
                          ]
                        }
                      ]
                      name "sr3(1)"
                      boundingObject USE r3
                      physics Physics {
                        density -1
                        mass 0.1
                      }
                    }
                  }
                  DEF sr2 HingeJoint {
                    jointParameters HingeJointParameters {
                      axis 0.707107 0.707107 0
                      anchor -0.03535 0.03535 0.02
                    }
                    endPoint Solid {
                      translation -0.03535 0.03535 0.02
                      rotation 0.7071067811865476 0.7071067811865476 0 0
                      children [
                        DEF r2 Transform {
                          rotation 0 0 1 2.27
                          children [
                            DEF SMALL_WHEEL_SHAPE Shape {
                              appearance PBRAppearance {
                                baseColor 1 0.752941 0.796078
                                roughness 1
                                metalness 0
                              }
                              geometry Capsule {
                                height 0.015
                                radius 0.01
                              }
                            }
                          ]
                        }
                      ]
                      name "sr2(1)"
                      boundingObject USE r2
                      physics Physics {
                        density -1
                        mass 0.1
                      }
                    }
                  }
                  DEF sr1 HingeJoint {
                    jointParameters HingeJointParameters {
                      anchor 0 0.05 0.02
                    }
                    endPoint Solid {
                      translation 0 0.05 0.02
                      rotation 1 0 0 0
                      children [
                        DEF r1 Transform {
                          rotation 0 0 1 1.5708
                          children [
                            DEF SMALL_WHEEL_SHAPE Shape {
                              appearance PBRAppearance {
                                baseColor 1 0.752941 0.796078
                                roughness 1
                                metalness 0
                              }
                              geometry Capsule {
                                height 0.015
                                radius 0.01
                              }
                            }
                          ]
                        }
                      ]
                      name "sr1(1)"
                      boundingObject USE r1
                      physics Physics {
                        density -1
                        mass 0.1
                      }
                    }
                  }
                ]
              }
              DEF Wheel_Half_B Transform {
                children [
                  DEF WHEEL_TRANS Transform {
                    translation 0 0 0.02
                    rotation 1 0 0 1.5708
                    children [
                      DEF WHEEL_SHAPE Shape {
                        appearance PBRAppearance {
                          baseColor 0.678431 0.847059 0.901961
                          roughness 1
                          metalness 0
                        }
                        geometry Cylinder {
                          height 0.02
                          radius 0.05
                          subdivision 20
                        }
                      }
                    ]
                  }
                  DEF sr8 HingeJoint {
                    jointParameters HingeJointParameters {
                      axis -0.707107 0.707107 0
                      anchor 0.03535 0.03535 0.02
                    }
                    endPoint Solid {
                      translation 0.03535 0.03535 0.02
                      rotation -0.7071067811865476 0.7071067811865476 0 0
                      children [
                        DEF r8 Transform {
                          rotation 0 0 1 0.76
                          children [
                            DEF SMALL_WHEEL_SHAPE Shape {
                              appearance PBRAppearance {
                                baseColor 1 0.752941 0.796078
                                roughness 1
                                metalness 0
                              }
                              geometry Capsule {
                                height 0.015
                                radius 0.01
                              }
                            }
                          ]
                        }
                      ]
                      name "sr8"
                      boundingObject USE r8
                      physics Physics {
                        density -1
                        mass 0.1
                      }
                    }
                  }
                  DEF sr7 HingeJoint {
                    jointParameters HingeJointParameters {
                      axis -0.707107 0.707107 0
                      anchor -0.03535 -0.03535 0.02
                    }
                    endPoint Solid {
                      translation -0.03535 -0.03535 0.02
                      rotation -0.7071067811865476 0.7071067811865476 0 0
                      children [
                        DEF r7 Transform {
                          rotation 0 0 1 0.76
                          children [
                            DEF SMALL_WHEEL_SHAPE Shape {
                              appearance PBRAppearance {
                                baseColor 1 0.752941 0.796078
                                roughness 1
                                metalness 0
                              }
                              geometry Capsule {
                                height 0.015
                                radius 0.01
                              }
                            }
                          ]
                        }
                      ]
                      name "sr7"
                      boundingObject USE r7
                      physics Physics {
                        density -1
                        mass 0.1
                      }
                    }
                  }
                  DEF sr6 HingeJoint {
                    jointParameters HingeJointParameters {
                      axis 0 1 0
                      anchor 0.05 0 0.02
                    }
                    endPoint Solid {
                      translation 0.05 0 0.02
                      children [
                        DEF r6 Transform {
                          children [
                            DEF SMALL_WHEEL_SHAPE Shape {
                              appearance PBRAppearance {
                                baseColor 1 0.752941 0.796078
                                roughness 1
                                metalness 0
                              }
                              geometry Capsule {
                                height 0.015
                                radius 0.01
                              }
                            }
                          ]
                        }
                      ]
                      name "sr6"
                      boundingObject USE r6
                      physics Physics {
                        density -1
                        mass 0.1
                      }
                    }
                  }
                  DEF sr5 HingeJoint {
                    jointParameters HingeJointParameters {
                      axis 0 1 0
                      anchor -0.05 0 0.02
                    }
                    endPoint Solid {
                      translation -0.05 0 0.02
                      children [
                        DEF r5 Transform {
                          children [
                            DEF SMALL_WHEEL_SHAPE Shape {
                              appearance PBRAppearance {
                                baseColor 1 0.752941 0.796078
                                roughness 1
                                metalness 0
                              }
                              geometry Capsule {
                                height 0.015
                                radius 0.01
                              }
                            }
                          ]
                        }
                      ]
                      name "sr5"
                      boundingObject USE r5
                      physics Physics {
                        density -1
                        mass 0.1
                      }
                    }
                  }
                  DEF sr4 HingeJoint {
                    jointParameters HingeJointParameters {
                      axis 0.707107 0.707107 0
                      anchor 0.03535 -0.03535 0.02
                    }
                    endPoint Solid {
                      translation 0.03535 -0.03535 0.02
                      rotation 0.7071067811865476 0.7071067811865476 0 0
                      children [
                        DEF r4 Transform {
                          rotation 0 0 1 2.27
                          children [
                            DEF SMALL_WHEEL_SHAPE Shape {
                              appearance PBRAppearance {
                                baseColor 1 0.752941 0.796078
                                roughness 1
                                metalness 0
                              }
                              geometry Capsule {
                                height 0.015
                                radius 0.01
                              }
                            }
                          ]
                        }
                      ]
                      name "sr4"
                      boundingObject USE r4
                      physics Physics {
                        density -1
                        mass 0.1
                      }
                    }
                  }
                  DEF sr3 HingeJoint {
                    jointParameters HingeJointParameters {
                      anchor 0 -0.05 0.02
                    }
                    endPoint Solid {
                      translation 0 -0.05 0.02
                      rotation 1 0 0 0
                      children [
                        DEF r3 Transform {
                          rotation 0 0 1 1.5708
                          children [
                            DEF SMALL_WHEEL_SHAPE Shape {
                              appearance PBRAppearance {
                                baseColor 1 0.752941 0.796078
                                roughness 1
                                metalness 0
                              }
                              geometry Capsule {
                                height 0.015
                                radius 0.01
                              }
                            }
                          ]
                        }
                      ]
                      name "sr3"
                      boundingObject USE r3
                      physics Physics {
                        density -1
                        mass 0.1
                      }
                    }
                  }
                  DEF sr2 HingeJoint {
                    jointParameters HingeJointParameters {
                      axis 0.707107 0.707107 0
                      anchor -0.03535 0.03535 0.02
                    }
                    endPoint Solid {
                      translation -0.03535 0.03535 0.02
                      rotation 0.7071067811865476 0.7071067811865476 0 0
                      children [
                        DEF r2 Transform {
                          rotation 0 0 1 2.27
                          children [
                            DEF SMALL_WHEEL_SHAPE Shape {
                              appearance PBRAppearance {
                                baseColor 1 0.752941 0.796078
                                roughness 1
                                metalness 0
                              }
                              geometry Capsule {
                                height 0.015
                                radius 0.01
                              }
                            }
                          ]
                        }
                      ]
                      name "sr2"
                      boundingObject USE r2
                      physics Physics {
                        density -1
                        mass 0.1
                      }
                    }
                  }
                  DEF sr1 HingeJoint {
                    jointParameters HingeJointParameters {
                      anchor 0 0.05 0.02
                    }
                    endPoint Solid {
                      translation 0 0.05 0.02
                      rotation 1 0 0 0
                      children [
                        DEF r1 Transform {
                          rotation 0 0 1 1.5708
                          children [
                            DEF SMALL_WHEEL_SHAPE Shape {
                              appearance PBRAppearance {
                                baseColor 1 0.752941 0.796078
                                roughness 1
                                metalness 0
                              }
                              geometry Capsule {
                                height 0.015
                                radius 0.01
                              }
                            }
                          ]
                        }
                      ]
                      name "sr1"
                      boundingObject USE r1
                      physics Physics {
                        density -1
                        mass 0.1
                      }
                    }
                  }
                ]
              }
            ]
            boundingObject Transform {
              translation 0 0 0.02
              rotation 1 0 0 1.5708
              children [
                DEF wheel1 Shape {
                  appearance PBRAppearance {
                    baseColor 0.8 0.8 0.8
                    transparency 0.12999999523162842
                    roughness 1
                    metalness 0
                    emissiveColor 0 1 0
                  }
                  geometry Cylinder {
                    height 0.02
                    radius 0.05
                  }
                }
              ]
            }
            physics Physics {
            }
          }
        }
      ]
      name "wheel 1(1)"
      boundingObject USE dummy_object
      physics Physics {
      }
    }
    DEF wheel3 Solid {
      translation -0.0272474 -0.134142 -0.0157312
      rotation 0.2157390014202098 -0.9021230059386757 0.37367200245988275 2.18123
      children [
        DEF WHEEL1 HingeJoint {
          jointParameters HingeJointParameters {
            axis 0 0 1
            anchor 0 0 0.1
            suspensionSpringConstant 50000
            suspensionDampingConstant 10000
            suspensionAxis 0 1 0
          }
          device [
            RotationalMotor {
              name "wheel3"
              maxVelocity 50
            }
          ]
          endPoint Solid {
            translation 0 0 0.1
            rotation 0 0 1 0
            children [
              DEF Wheel_Half_B Transform {
                children [
                  DEF WHEEL_TRANS Transform {
                    translation 0 0 0.02
                    rotation 1 0 0 1.5708
                    children [
                      DEF WHEEL_SHAPE Shape {
                        appearance PBRAppearance {
                          baseColor 0.678431 0.847059 0.901961
                          roughness 1
                          metalness 0
                        }
                        geometry Cylinder {
                          height 0.02
                          radius 0.05
                          subdivision 20
                        }
                      }
                    ]
                  }
                  DEF sr8 HingeJoint {
                    jointParameters HingeJointParameters {
                      axis -0.707107 0.707107 0
                      anchor 0.03535 0.03535 0.02
                    }
                    endPoint Solid {
                      translation 0.03535 0.03535 0.02
                      rotation -0.7071067811865476 0.7071067811865476 0 0
                      children [
                        DEF r8 Transform {
                          rotation 0 0 1 0.76
                          children [
                            DEF SMALL_WHEEL_SHAPE Shape {
                              appearance PBRAppearance {
                                baseColor 1 0.752941 0.796078
                                roughness 1
                                metalness 0
                              }
                              geometry Capsule {
                                height 0.015
                                radius 0.01
                              }
                            }
                          ]
                        }
                      ]
                      name "sr8"
                      boundingObject USE r8
                      physics Physics {
                        density -1
                        mass 0.1
                      }
                    }
                  }
                  DEF sr7 HingeJoint {
                    jointParameters HingeJointParameters {
                      axis -0.707107 0.707107 0
                      anchor -0.03535 -0.03535 0.02
                    }
                    endPoint Solid {
                      translation -0.03535 -0.03535 0.02
                      rotation -0.7071067811865476 0.7071067811865476 0 0
                      children [
                        DEF r7 Transform {
                          rotation 0 0 1 0.76
                          children [
                            DEF SMALL_WHEEL_SHAPE Shape {
                              appearance PBRAppearance {
                                baseColor 1 0.752941 0.796078
                                roughness 1
                                metalness 0
                              }
                              geometry Capsule {
                                height 0.015
                                radius 0.01
                              }
                            }
                          ]
                        }
                      ]
                      name "sr7"
                      boundingObject USE r7
                      physics Physics {
                        density -1
                        mass 0.1
                      }
                    }
                  }
                  DEF sr6 HingeJoint {
                    jointParameters HingeJointParameters {
                      axis 0 1 0
                      anchor 0.05 0 0.02
                    }
                    endPoint Solid {
                      translation 0.05 0 0.02
                      children [
                        DEF r6 Transform {
                          children [
                            DEF SMALL_WHEEL_SHAPE Shape {
                              appearance PBRAppearance {
                                baseColor 1 0.752941 0.796078
                                roughness 1
                                metalness 0
                              }
                              geometry Capsule {
                                height 0.015
                                radius 0.01
                              }
                            }
                          ]
                        }
                      ]
                      name "sr6"
                      boundingObject USE r6
                      physics Physics {
                        density -1
                        mass 0.1
                      }
                    }
                  }
                  DEF sr5 HingeJoint {
                    jointParameters HingeJointParameters {
                      axis 0 1 0
                      anchor -0.05 0 0.02
                    }
                    endPoint Solid {
                      translation -0.05 0 0.02
                      children [
                        DEF r5 Transform {
                          children [
                            DEF SMALL_WHEEL_SHAPE Shape {
                              appearance PBRAppearance {
                                baseColor 1 0.752941 0.796078
                                roughness 1
                                metalness 0
                              }
                              geometry Capsule {
                                height 0.015
                                radius 0.01
                              }
                            }
                          ]
                        }
                      ]
                      name "sr5"
                      boundingObject USE r5
                      physics Physics {
                        density -1
                        mass 0.1
                      }
                    }
                  }
                  DEF sr4 HingeJoint {
                    jointParameters HingeJointParameters {
                      axis 0.707107 0.707107 0
                      anchor 0.03535 -0.03535 0.02
                    }
                    endPoint Solid {
                      translation 0.03535 -0.03535 0.02
                      rotation 0.7071067811865476 0.7071067811865476 0 0
                      children [
                        DEF r4 Transform {
                          rotation 0 0 1 2.27
                          children [
                            DEF SMALL_WHEEL_SHAPE Shape {
                              appearance PBRAppearance {
                                baseColor 1 0.752941 0.796078
                                roughness 1
                                metalness 0
                              }
                              geometry Capsule {
                                height 0.015
                                radius 0.01
                              }
                            }
                          ]
                        }
                      ]
                      name "sr4"
                      boundingObject USE r4
                      physics Physics {
                        density -1
                        mass 0.1
                      }
                    }
                  }
                  DEF sr3 HingeJoint {
                    jointParameters HingeJointParameters {
                      anchor 0 -0.05 0.02
                    }
                    endPoint Solid {
                      translation 0 -0.05 0.02
                      rotation 1 0 0 0
                      children [
                        DEF r3 Transform {
                          rotation 0 0 1 1.5708
                          children [
                            DEF SMALL_WHEEL_SHAPE Shape {
                              appearance PBRAppearance {
                                baseColor 1 0.752941 0.796078
                                roughness 1
                                metalness 0
                              }
                              geometry Capsule {
                                height 0.015
                                radius 0.01
                              }
                            }
                          ]
                        }
                      ]
                      name "sr3"
                      boundingObject USE r3
                      physics Physics {
                        density -1
                        mass 0.1
                      }
                    }
                  }
                  DEF sr2 HingeJoint {
                    jointParameters HingeJointParameters {
                      axis 0.707107 0.707107 0
                      anchor -0.03535 0.03535 0.02
                    }
                    endPoint Solid {
                      translation -0.03535 0.03535 0.02
                      rotation 0.7071067811865476 0.7071067811865476 0 0
                      children [
                        DEF r2 Transform {
                          rotation 0 0 1 2.27
                          children [
                            DEF SMALL_WHEEL_SHAPE Shape {
                              appearance PBRAppearance {
                                baseColor 1 0.752941 0.796078
                                roughness 1
                                metalness 0
                              }
                              geometry Capsule {
                                height 0.015
                                radius 0.01
                              }
                            }
                          ]
                        }
                      ]
                      name "sr2"
                      boundingObject USE r2
                      physics Physics {
                        density -1
                        mass 0.1
                      }
                    }
                  }
                  DEF sr1 HingeJoint {
                    jointParameters HingeJointParameters {
                      anchor 0 0.05 0.02
                    }
                    endPoint Solid {
                      translation 0 0.05 0.02
                      rotation 1 0 0 0
                      children [
                        DEF r1 Transform {
                          rotation 0 0 1 1.5708
                          children [
                            DEF SMALL_WHEEL_SHAPE Shape {
                              appearance PBRAppearance {
                                baseColor 1 0.752941 0.796078
                                roughness 1
                                metalness 0
                              }
                              geometry Capsule {
                                height 0.015
                                radius 0.01
                              }
                            }
                          ]
                        }
                      ]
                      name "sr1"
                      boundingObject USE r1
                      physics Physics {
                        density -1
                        mass 0.1
                      }
                    }
                  }
                ]
              }
              DEF Wheel_Half_A Transform {
                translation 0 0 0.02
                rotation 0 0 1 0.39
                children [
                  DEF WHEEL_TRANS Transform {
                    translation 0 0 0.02
                    rotation 1 0 0 1.5708
                    children [
                      DEF WHEEL_SHAPE Shape {
                        appearance PBRAppearance {
                          baseColor 0.678431 0.847059 0.901961
                          roughness 1
                          metalness 0
                        }
                        geometry Cylinder {
                          height 0.02
                          radius 0.05
                          subdivision 20
                        }
                      }
                    ]
                  }
                  DEF sr8 HingeJoint {
                    jointParameters HingeJointParameters {
                      axis -0.707107 0.707107 0
                      anchor 0.03535 0.03535 0.02
                    }
                    endPoint Solid {
                      translation 0.03535 0.03535 0.02
                      rotation -0.7071067811865476 0.7071067811865476 0 0
                      children [
                        DEF r8 Transform {
                          rotation 0 0 1 0.76
                          children [
                            DEF SMALL_WHEEL_SHAPE Shape {
                              appearance PBRAppearance {
                                baseColor 1 0.752941 0.796078
                                roughness 1
                                metalness 0
                              }
                              geometry Capsule {
                                height 0.015
                                radius 0.01
                              }
                            }
                          ]
                        }
                      ]
                      name "sr8(1)"
                      boundingObject USE r8
                      physics Physics {
                        density -1
                        mass 0.1
                      }
                    }
                  }
                  DEF sr7 HingeJoint {
                    jointParameters HingeJointParameters {
                      axis -0.707107 0.707107 0
                      anchor -0.03535 -0.03535 0.02
                    }
                    endPoint Solid {
                      translation -0.03535 -0.03535 0.02
                      rotation -0.7071067811865476 0.7071067811865476 0 0
                      children [
                        DEF r7 Transform {
                          rotation 0 0 1 0.76
                          children [
                            DEF SMALL_WHEEL_SHAPE Shape {
                              appearance PBRAppearance {
                                baseColor 1 0.752941 0.796078
                                roughness 1
                                metalness 0
                              }
                              geometry Capsule {
                                height 0.015
                                radius 0.01
                              }
                            }
                          ]
                        }
                      ]
                      name "sr7(1)"
                      boundingObject USE r7
                      physics Physics {
                        density -1
                        mass 0.1
                      }
                    }
                  }
                  DEF sr6 HingeJoint {
                    jointParameters HingeJointParameters {
                      axis 0 1 0
                      anchor 0.05 0 0.02
                    }
                    endPoint Solid {
                      translation 0.05 0 0.02
                      children [
                        DEF r6 Transform {
                          children [
                            DEF SMALL_WHEEL_SHAPE Shape {
                              appearance PBRAppearance {
                                baseColor 1 0.752941 0.796078
                                roughness 1
                                metalness 0
                              }
                              geometry Capsule {
                                height 0.015
                                radius 0.01
                              }
                            }
                          ]
                        }
                      ]
                      name "sr6(1)"
                      boundingObject USE r6
                      physics Physics {
                        density -1
                        mass 0.1
                      }
                    }
                  }
                  DEF sr5 HingeJoint {
                    jointParameters HingeJointParameters {
                      axis 0 1 0
                      anchor -0.05 0 0.02
                    }
                    endPoint Solid {
                      translation -0.05 0 0.02
                      children [
                        DEF r5 Transform {
                          children [
                            DEF SMALL_WHEEL_SHAPE Shape {
                              appearance PBRAppearance {
                                baseColor 1 0.752941 0.796078
                                roughness 1
                                metalness 0
                              }
                              geometry Capsule {
                                height 0.015
                                radius 0.01
                              }
                            }
                          ]
                        }
                      ]
                      name "sr5(1)"
                      boundingObject USE r5
                      physics Physics {
                        density -1
                        mass 0.1
                      }
                    }
                  }
                  DEF sr4 HingeJoint {
                    jointParameters HingeJointParameters {
                      axis 0.707107 0.707107 0
                      anchor 0.03535 -0.03535 0.02
                    }
                    endPoint Solid {
                      translation 0.03535 -0.03535 0.02
                      rotation 0.7071067811865476 0.7071067811865476 0 0
                      children [
                        DEF r4 Transform {
                          rotation 0 0 1 2.27
                          children [
                            DEF SMALL_WHEEL_SHAPE Shape {
                              appearance PBRAppearance {
                                baseColor 1 0.752941 0.796078
                                roughness 1
                                metalness 0
                              }
                              geometry Capsule {
                                height 0.015
                                radius 0.01
                              }
                            }
                          ]
                        }
                      ]
                      name "sr4(1)"
                      boundingObject USE r4
                      physics Physics {
                        density -1
                        mass 0.1
                      }
                    }
                  }
                  DEF sr3 HingeJoint {
                    jointParameters HingeJointParameters {
                      anchor 0 -0.05 0.02
                    }
                    endPoint Solid {
                      translation 0 -0.05 0.02
                      rotation 1 0 0 0
                      children [
                        DEF r3 Transform {
                          rotation 0 0 1 1.5708
                          children [
                            DEF SMALL_WHEEL_SHAPE Shape {
                              appearance PBRAppearance {
                                baseColor 1 0.752941 0.796078
                                roughness 1
                                metalness 0
                              }
                              geometry Capsule {
                                height 0.015
                                radius 0.01
                              }
                            }
                          ]
                        }
                      ]
                      name "sr3(1)"
                      boundingObject USE r3
                      physics Physics {
                        density -1
                        mass 0.1
                      }
                    }
                  }
                  DEF sr2 HingeJoint {
                    jointParameters HingeJointParameters {
                      axis 0.707107 0.707107 0
                      anchor -0.03535 0.03535 0.02
                    }
                    endPoint Solid {
                      translation -0.03535 0.03535 0.02
                      rotation 0.7071067811865476 0.7071067811865476 0 0
                      children [
                        DEF r2 Transform {
                          rotation 0 0 1 2.27
                          children [
                            DEF SMALL_WHEEL_SHAPE Shape {
                              appearance PBRAppearance {
                                baseColor 1 0.752941 0.796078
                                roughness 1
                                metalness 0
                              }
                              geometry Capsule {
                                height 0.015
                                radius 0.01
                              }
                            }
                          ]
                        }
                      ]
                      name "sr2(1)"
                      boundingObject USE r2
                      physics Physics {
                        density -1
                        mass 0.1
                      }
                    }
                  }
                  DEF sr1 HingeJoint {
                    jointParameters HingeJointParameters {
                      anchor 0 0.05 0.02
                    }
                    endPoint Solid {
                      translation 0 0.05 0.02
                      rotation 1 0 0 0
                      children [
                        DEF r1 Transform {
                          rotation 0 0 1 1.5708
                          children [
                            DEF SMALL_WHEEL_SHAPE Shape {
                              appearance PBRAppearance {
                                baseColor 1 0.752941 0.796078
                                roughness 1
                                metalness 0
                              }
                              geometry Capsule {
                                height 0.015
                                radius 0.01
                              }
                            }
                          ]
                        }
                      ]
                      name "sr1(1)"
                      boundingObject USE r1
                      physics Physics {
                        density -1
                        mass 0.1
                      }
                    }
                  }
                ]
              }
            ]
            boundingObject Transform {
              translation 0 0 0.02
              rotation 1 0 0 1.5708
              children [
                DEF wheel1 Shape {
                  appearance PBRAppearance {
                    baseColor 0.8 0.8 0.8
                    transparency 0.12999999523162842
                    roughness 1
                    metalness 0
                    emissiveColor 0 1 0
                  }
                  geometry Cylinder {
                    height 0.02
                    radius 0.05
                  }
                }
              ]
            }
            physics Physics {
            }
          }
        }
      ]
      name "wheel 1(2)"
      boundingObject USE dummy_object
      physics Physics {
      }
    }
    DEF BODY_TRANS Transform {
      translation 0 0.11 0
      children [
        Shape {
          appearance PBRAppearance {
            baseColor 0.564706 0.933333 0.564706
            roughness 1
            metalness 0
          }
          geometry Cylinder {
            height 0.5
            radius 0.1
            subdivision 18
          }
        }
      ]
    }
  ]
  boundingObject USE BODY_TRANS
  physics Physics {
    density -1
    mass 5
    centerOfMass [
      0 0.25 0
    ]
    inertiaMatrix [
      0.5235987755982989 0.07853981633974486 0.5235987755982989
      0 0 0
    ]
  }
  controller "cntrIP"
}
Robot {
  translation 0 0.14 0
  children [
    Shape {
      appearance Copper {
      }
      geometry DEF sphere_geom Sphere {
        radius 0.14
        subdivision 4
      }
    }
  ]
  name "robot(1)"
  boundingObject USE sphere_geom
  physics Physics {
    density -1
    mass 1
    centerOfMass [
      0 0 0
    ]
    inertiaMatrix [
      0.1272345024703866 0.1272345024703866 0.1272345024703866
      0 0 0
    ]
  }
}
